Workbook
Name _Sem2: #REF!
Name _Sem2: #REF!
Name _Sem2: #REF!
Name _Sem2: #REF!
Name _Sem2: #REF!
Name _Sem2: #REF!
Name _Sem2: #REF!
Name _Sem2: #REF!
Name _Sem2: #REF!
Name _Sem2: #REF!
Name _Sem2: #REF!
Name _Sem2: #REF!
Name _Sem2: #REF!
Name _Sem2: #REF!

Sheet Guia para usar

Sheet Fluxo de Caixa
A1: Rev.00 - 01/01/2026
A3: Ano 2026 - DESPESAS | G3: =COUNTIF(A5:F5,"<>-") -> 0 | I3: Ano 2026 - RECEITAS | O3: =COUNTIF(I5:N5,"<>-") -> 0 | Q3: Ano 2026 - BALANÇO LÍQUIDO | W3: =COUNTIF(Q5:V5,"<>-") -> 0
A4: Jan'26 | B4: Fev'26 | C4: Mar'26 | D4: Abr'26 | E4: Mai'26 | F4: Jun'26 | G4: =COUNTIF(A9:F9,"<>-") -> 0 | I4: Jan'26 | J4: Fev'26 | K4: Mar'26 | L4: Abr'26 | M4: Mai'26 | N4: Jun'26 | O4: =COUNTIF(I9:N9,"<>-") -> 0 | Q4: Jan'26 | R4: Fev'26 | S4: Mar'26 | T4: Abr'26 | U4: Mai'26 | V4: Jun'26 | W4: =COUNTIF(Q9:V9,"<>-") -> 0
A5: =IF('Jan''26'!B102=0,"-",'Jan''26'!B102) -> - | B5: =IF('Fev''26'!B102=0,"-",'Fev''26'!B102) -> - | C5: =IF('Mar''26'!B102=0,"-",'Mar''26'!B102) -> - | D5: =IF('Abr''26'!B102=0,"-",'Abr''26'!B102) -> - | E5: =IF('Mai''26'!B102=0,"-",'Mai''26'!B102) -> - | F5: =IF('Jun''26'!B102=0,"-",'Jun''26'!B102) -> - | G5: =SUM(G3:G4) -> 0 | I5: =IF(Receitas!B14=0,"-",Receitas!B14) -> - | J5: =IF(Receitas!D14=0,"-",Receitas!D14) -> - | K5: =IF(Receitas!F14=0,"-",Receitas!F14) -> - | L5: =IF(Receitas!H14=0,"-",Receitas!H14) -> - | M5: =IF(Receitas!J14=0,"-",Receitas!J14) -> - | N5: =IF(Receitas!L14=0,"-",Receitas!L14) -> - | O5: =SUM(O3:O4) -> 0 | Q5: =IF(OR(A5="-",I5="-"),"-",I5-A5) -> - | R5: =IF(OR(B5="-",J5="-"),"-",J5-B5) -> - | S5: =IF(OR(C5="-",K5="-"),"-",K5-C5) -> - | T5: =IF(OR(D5="-",L5="-"),"-",L5-D5) -> - | U5: =IF(OR(E5="-",M5="-"),"-",M5-E5) -> - | V5: =IF(OR(F5="-",N5="-"),"-",N5-F5) -> - | W5: =SUM(W3:W4) -> 0
Q6: =IF(OR(A5="-",I5="-"),"-",Q5/I5) -> - | R6: =IF(OR(B5="-",J5="-"),"-",R5/J5) -> - | S6: =IF(OR(C5="-",K5="-"),"-",S5/K5) -> - | T6: =IF(OR(D5="-",L5="-"),"-",T5/L5) -> - | U6: =IF(OR(E5="-",M5="-"),"-",U5/M5) -> - | V6: =IF(OR(F5="-",N5="-"),"-",V5/N5) -> -
A8: Jul'26 | B8: Ago'26 | C8: Set'26 | D8: Out'26 | E8: Nov'26 | F8: Dez'26 | I8: Jul'26 | J8: Ago'26 | K8: Set'26 | L8: Out'26 | M8: Nov'26 | N8: Dez'26 | Q8: Jul'26 | R8: Ago'26 | S8: Set'26 | T8: Out'26 | U8: Nov'26 | V8: Dez'26
A9: =IF('Jul''26'!B102=0,"-",'Jul''26'!B102) -> - | B9: =IF('Ago''26'!B102=0,"-",'Ago''26'!B102) -> - | C9: =IF('Set''26'!B102=0,"-",'Set''26'!B102) -> - | D9: =IF('Out''26'!B102=0,"-",'Out''26'!B102) -> - | E9: =IF('Nov''26'!B102=0,"-",'Nov''26'!B102) -> - | F9: =IF('Dez''26'!B102=0,"-",'Dez''26'!B102) -> - | I9: =IF(Receitas!B27=0,"-",Receitas!B27) -> - | J9: =IF(Receitas!D27=0,"-",Receitas!D27) -> - | K9: =IF(Receitas!F27=0,"-",Receitas!F27) -> - | L9: =IF(Receitas!H27=0,"-",Receitas!H27) -> - | M9: =IF(Receitas!J27=0,"-",Receitas!J27) -> - | N9: =IF(Receitas!L27=0,"-",Receitas!L27) -> - | Q9: =IF(OR(A9="-",I9="-"),"-",I9-A9) -> - | R9: =IF(OR(B9="-",J9="-"),"-",J9-B9) -> - | S9: =IF(OR(C9="-",K9="-"),"-",K9-C9) -> - | T9: =IF(OR(D9="-",L9="-"),"-",L9-D9) -> - | U9: =IF(OR(E9="-",M9="-"),"-",M9-E9) -> - | V9: =IF(OR(F9="-",N9="-"),"-",N9-F9) -> -
Q10: =IF(OR(A9="-",I9="-"),"-",Q9/I9) -> - | R10: =IF(OR(B9="-",J9="-"),"-",R9/J9) -> - | S10: =IF(OR(C9="-",K9="-"),"-",S9/K9) -> - | T10: =IF(OR(D9="-",L9="-"),"-",T9/L9) -> - | U10: =IF(OR(E9="-",M9="-"),"-",U9/M9) -> - | V10: =IF(OR(F9="-",N9="-"),"-",V9/N9) -> -
B12: Total Despesas 2026 | C12: =SUM(A5:F5,A9:F9) -> 0 | J12: Total Receitas 2026 | K12: =SUM(I5:N5,I9:N9) -> 0 | R12: Total Balanço Líquido 2026 | S12: =SUM(Q5:V5,Q9:V9) -> 0
B14: Média Despesas por mês | C14: =IF(C12=0,"-",C12/G5) -> - | J14: Média Receita por mês | K14: =IF(K12=0,"-",K12/O5) -> - | R14: Média Balanço Líquido por mês | S14: =IF(S12=0,"-",S12/W5) -> - | U14: Média final Balanço Líquido | V14: =IF(S12=0,"-",S12/K12) -> -

Sheet Despesas
A1: Rev.00 - 01/01/2026
A3: Janeiro 2026 | E3: Fevereiro 2026 | I3: Março 2026 | P3: Despesas Ano de 2026 - compilado
A4: Origem da Despesa | B4: Valor | C4: Porcentagem | E4: Origem da Despesa | F4: Valor | G4: Porcentagem | I4: Origem da Despesa | J4: Valor | K4: Porcentagem | P4: Origem da Despesa | Q4: Valor | R4: Porcentagem
A5: Alimentação / Nutrição | B5: ='Jan''26'!J3 -> 0 | C5: =IF($B$18=0,"-",B5/$B$18) -> - | E5: Alimentação / Nutrição | F5: ='Fev''26'!J3 -> 0 | G5: =IF($F$18=0,"-",F5/$F$18) -> - | I5: Alimentação / Nutrição | J5: ='Mar''26'!J3 -> 0 | K5: =IF($J$18=0,"-",J5/$J$18) -> - | P5: Alimentação / Nutrição | Q5: =SUM(B5,F5,J5,B23,F23,J23,B41,F41,J41,B59,F59,J59) -> 0 | R5: =IF(Q5=0,"-",Q5/$Q$18) -> -
A6: Carro / Transporte | B6: ='Jan''26'!J4 -> 0 | C6: =IF($B$18=0,"-",B6/$B$18) -> - | E6: Carro / Transporte | F6: ='Fev''26'!J4 -> 0 | G6: =IF($F$18=0,"-",F6/$F$18) -> - | I6: Carro / Transporte | J6: ='Mar''26'!J4 -> 0 | K6: =IF($J$18=0,"-",J6/$J$18) -> - | P6: Carro / Transporte | Q6: =SUM(B6,F6,J6,B24,F24,J24,B42,F42,J42,B60,F60,J60) -> 0 | R6: =IF(Q6=0,"-",Q6/$Q$18) -> -
A7: Casa / Moradia | B7: ='Jan''26'!J5 -> 0 | C7: =IF($B$18=0,"-",B7/$B$18) -> - | E7: Casa / Moradia | F7: ='Fev''26'!J5 -> 0 | G7: =IF($F$18=0,"-",F7/$F$18) -> - | I7: Casa / Moradia | J7: ='Mar''26'!J5 -> 0 | K7: =IF($J$18=0,"-",J7/$J$18) -> - | P7: Casa / Moradia | Q7: =SUM(B7,F7,J7,B25,F25,J25,B43,F43,J43,B61,F61,J61) -> 0 | R7: =IF(Q7=0,"-",Q7/$Q$18) -> -
A8: Celular / Computador | B8: ='Jan''26'!J6 -> 0 | C8: =IF($B$18=0,"-",B8/$B$18) -> - | E8: Celular / Computador | F8: ='Fev''26'!J6 -> 0 | G8: =IF($F$18=0,"-",F8/$F$18) -> - | I8: Celular / Computador | J8: ='Mar''26'!J6 -> 0 | K8: =IF($J$18=0,"-",J8/$J$18) -> - | P8: Celular / Computador | Q8: =SUM(B8,F8,J8,B26,F26,J26,B44,F44,J44,B62,F62,J62) -> 0 | R8: =IF(Q8=0,"-",Q8/$Q$18) -> -
A9: Desenvolvimento Pessoal | B9: ='Jan''26'!J7 -> 0 | C9: =IF($B$18=0,"-",B9/$B$18) -> - | E9: Desenvolvimento Pessoal | F9: ='Fev''26'!J7 -> 0 | G9: =IF($F$18=0,"-",F9/$F$18) -> - | I9: Desenvolvimento Pessoal | J9: ='Mar''26'!J7 -> 0 | K9: =IF($J$18=0,"-",J9/$J$18) -> - | P9: Desenvolvimento Pessoal | Q9: =SUM(B9,F9,J9,B27,F27,J27,B45,F45,J45,B63,F63,J63) -> 0 | R9: =IF(Q9=0,"-",Q9/$Q$18) -> -
A10: Farmácia / Medicamentos | B10: ='Jan''26'!J8 -> 0 | C10: =IF($B$18=0,"-",B10/$B$18) -> - | E10: Farmácia / Medicamentos | F10: ='Fev''26'!J8 -> 0 | G10: =IF($F$18=0,"-",F10/$F$18) -> - | I10: Farmácia / Medicamentos | J10: ='Mar''26'!J8 -> 0 | K10: =IF($J$18=0,"-",J10/$J$18) -> - | P10: Farmácia / Medicamentos | Q10: =SUM(B10,F10,J10,B28,F28,J28,B46,F46,J46,B64,F64,J64) -> 0 | R10: =IF(Q10=0,"-",Q10/$Q$18) -> -
A11: Filantropia / Doação | B11: ='Jan''26'!J9 -> 0 | C11: =IF($B$18=0,"-",B11/$B$18) -> - | E11: Filantropia / Doação | F11: ='Fev''26'!J9 -> 0 | G11: =IF($F$18=0,"-",F11/$F$18) -> - | I11: Filantropia / Doação | J11: ='Mar''26'!J9 -> 0 | K11: =IF($J$18=0,"-",J11/$J$18) -> - | P11: Filantropia / Doação | Q11: =SUM(B11,F11,J11,B29,F29,J29,B47,F47,J47,B65,F65,J65) -> 0 | R11: =IF(Q11=0,"-",Q11/$Q$18) -> -
A12: Higiene / Estética / Bem-estar | B12: ='Jan''26'!J10 -> 0 | C12: =IF($B$18=0,"-",B12/$B$18) -> - | E12: Higiene / Estética / Bem-estar | F12: ='Fev''26'!J10 -> 0 | G12: =IF($F$18=0,"-",F12/$F$18) -> - | I12: Higiene / Estética / Bem-estar | J12: ='Mar''26'!J10 -> 0 | K12: =IF($J$18=0,"-",J12/$J$18) -> - | P12: Higiene / Estética / Bem-estar | Q12: =SUM(B12,F12,J12,B30,F30,J30,B48,F48,J48,B66,F66,J66) -> 0 | R12: =IF(Q12=0,"-",Q12/$Q$18) -> -
A13: Lazer / Supérfluos | B13: ='Jan''26'!J11 -> 0 | C13: =IF($B$18=0,"-",B13/$B$18) -> - | E13: Lazer / Supérfluos | F13: ='Fev''26'!J11 -> 0 | G13: =IF($F$18=0,"-",F13/$F$18) -> - | I13: Lazer / Supérfluos | J13: ='Mar''26'!J11 -> 0 | K13: =IF($J$18=0,"-",J13/$J$18) -> - | P13: Lazer / Supérfluos | Q13: =SUM(B13,F13,J13,B31,F31,J31,B49,F49,J49,B67,F67,J67) -> 0 | R13: =IF(Q13=0,"-",Q13/$Q$18) -> -
A14: Miscelâneas | B14: ='Jan''26'!J12 -> 0 | C14: =IF($B$18=0,"-",B14/$B$18) -> - | E14: Miscelâneas | F14: ='Fev''26'!J12 -> 0 | G14: =IF($F$18=0,"-",F14/$F$18) -> - | I14: Miscelâneas | J14: ='Mar''26'!J12 -> 0 | K14: =IF($J$18=0,"-",J14/$J$18) -> - | P14: Miscelâneas | Q14: =SUM(B14,F14,J14,B32,F32,J32,B50,F50,J50,B68,F68,J68) -> 0 | R14: =IF(Q14=0,"-",Q14/$Q$18) -> -
A15: Vestuário | B15: ='Jan''26'!J13 -> 0 | C15: =IF($B$18=0,"-",B15/$B$18) -> - | E15: Vestuário | F15: ='Fev''26'!J13 -> 0 | G15: =IF($F$18=0,"-",F15/$F$18) -> - | I15: Vestuário | J15: ='Mar''26'!J13 -> 0 | K15: =IF($J$18=0,"-",J15/$J$18) -> - | P15: Vestuário | Q15: =SUM(B15,F15,J15,B33,F33,J33,B51,F51,J51,B69,F69,J69) -> 0 | R15: =IF(Q15=0,"-",Q15/$Q$18) -> -
A16: Viagem / Passeios / Turismo | B16: ='Jan''26'!J14 -> 0 | C16: =IF($B$18=0,"-",B16/$B$18) -> - | E16: Viagem / Passeios / Turismo | F16: ='Fev''26'!J14 -> 0 | G16: =IF($F$18=0,"-",F16/$F$18) -> - | I16: Viagem / Passeios / Turismo | J16: ='Mar''26'!J14 -> 0 | K16: =IF($J$18=0,"-",J16/$J$18) -> - | P16: Viagem / Passeios / Turismo | Q16: =SUM(B16,F16,J16,B34,F34,J34,B52,F52,J52,B70,F70,J70) -> 0 | R16: =IF(Q16=0,"-",Q16/$Q$18) -> -
A18: Total | B18: =SUM(B5:B16) -> 0 | C18: =SUM(C5:C16) -> 0 | E18: Total | F18: =SUM(F5:F16) -> 0 | G18: =SUM(G5:G16) -> 0 | I18: Total | J18: =SUM(J5:J16) -> 0 | K18: =SUM(K5:K16) -> 0 | P18: Total | Q18: =SUM(Q5:Q16) -> 0 | R18: =SUM(R5:R16) -> 0
A21: Abril 2026 | E21: Maio 2026 | I21: Junho 2026
A22: Origem da Despesa | B22: Valor | C22: Porcentagem | E22: Origem da Despesa | F22: Valor | G22: Porcentagem | I22: Origem da Despesa | J22: Valor | K22: Porcentagem
A23: Alimentação / Nutrição | B23: ='Abr''26'!J3 -> 0 | C23: =IF($B$36=0,"-",B23/$B$36) -> - | E23: Alimentação / Nutrição | F23: ='Mai''26'!J3 -> 0 | G23: =IF($F$36=0,"-",F23/$F$36) -> - | I23: Alimentação / Nutrição | J23: ='Jun''26'!J3 -> 0 | K23: =IF($J$36=0,"-",J23/$J$36) -> -
A24: Carro / Transporte | B24: ='Abr''26'!J4 -> 0 | C24: =IF($B$36=0,"-",B24/$B$36) -> - | E24: Carro / Transporte | F24: ='Mai''26'!J4 -> 0 | G24: =IF($F$36=0,"-",F24/$F$36) -> - | I24: Carro / Transporte | J24: ='Jun''26'!J4 -> 0 | K24: =IF($J$36=0,"-",J24/$J$36) -> -
A25: Casa / Moradia | B25: ='Abr''26'!J5 -> 0 | C25: =IF($B$36=0,"-",B25/$B$36) -> - | E25: Casa / Moradia | F25: ='Mai''26'!J5 -> 0 | G25: =IF($F$36=0,"-",F25/$F$36) -> - | I25: Casa / Moradia | J25: ='Jun''26'!J5 -> 0 | K25: =IF($J$36=0,"-",J25/$J$36) -> -
A26: Celular / Computador | B26: ='Abr''26'!J6 -> 0 | C26: =IF($B$36=0,"-",B26/$B$36) -> - | E26: Celular / Computador | F26: ='Mai''26'!J6 -> 0 | G26: =IF($F$36=0,"-",F26/$F$36) -> - | I26: Celular / Computador | J26: ='Jun''26'!J6 -> 0 | K26: =IF($J$36=0,"-",J26/$J$36) -> -
A27: Desenvolvimento Pessoal | B27: ='Abr''26'!J7 -> 0 | C27: =IF($B$36=0,"-",B27/$B$36) -> - | E27: Desenvolvimento Pessoal | F27: ='Mai''26'!J7 -> 0 | G27: =IF($F$36=0,"-",F27/$F$36) -> - | I27: Desenvolvimento Pessoal | J27: ='Jun''26'!J7 -> 0 | K27: =IF($J$36=0,"-",J27/$J$36) -> -
A28: Farmácia / Medicamentos | B28: ='Abr''26'!J8 -> 0 | C28: =IF($B$36=0,"-",B28/$B$36) -> - | E28: Farmácia / Medicamentos | F28: ='Mai''26'!J8 -> 0 | G28: =IF($F$36=0,"-",F28/$F$36) -> - | I28: Farmácia / Medicamentos | J28: ='Jun''26'!J8 -> 0 | K28: =IF($J$36=0,"-",J28/$J$36) -> -
A29: Filantropia / Doação | B29: ='Abr''26'!J9 -> 0 | C29: =IF($B$36=0,"-",B29/$B$36) -> - | E29: Filantropia / Doação | F29: ='Mai''26'!J9 -> 0 | G29: =IF($F$36=0,"-",F29/$F$36) -> - | I29: Filantropia / Doação | J29: ='Jun''26'!J9 -> 0 | K29: =IF($J$36=0,"-",J29/$J$36) -> -
A30: Higiene / Estética / Bem-estar | B30: ='Abr''26'!J10 -> 0 | C30: =IF($B$36=0,"-",B30/$B$36) -> - | E30: Higiene / Estética / Bem-estar | F30: ='Mai''26'!J10 -> 0 | G30: =IF($F$36=0,"-",F30/$F$36) -> - | I30: Higiene / Estética / Bem-estar | J30: ='Jun''26'!J10 -> 0 | K30: =IF($J$36=0,"-",J30/$J$36) -> -
A31: Lazer / Supérfluos | B31: ='Abr''26'!J11 -> 0 | C31: =IF($B$36=0,"-",B31/$B$36) -> - | E31: Lazer / Supérfluos | F31: ='Mai''26'!J11 -> 0 | G31: =IF($F$36=0,"-",F31/$F$36) -> - | I31: Lazer / Supérfluos | J31: ='Jun''26'!J11 -> 0 | K31: =IF($J$36=0,"-",J31/$J$36) -> -
A32: Miscelâneas | B32: ='Abr''26'!J12 -> 0 | C32: =IF($B$36=0,"-",B32/$B$36) -> - | E32: Miscelâneas | F32: ='Mai''26'!J12 -> 0 | G32: =IF($F$36=0,"-",F32/$F$36) -> - | I32: Miscelâneas | J32: ='Jun''26'!J12 -> 0 | K32: =IF($J$36=0,"-",J32/$J$36) -> -
A33: Vestuário | B33: ='Abr''26'!J13 -> 0 | C33: =IF($B$36=0,"-",B33/$B$36) -> - | E33: Vestuário | F33: ='Mai''26'!J13 -> 0 | G33: =IF($F$36=0,"-",F33/$F$36) -> - | I33: Vestuário | J33: ='Jun''26'!J13 -> 0 | K33: =IF($J$36=0,"-",J33/$J$36) -> -
A34: Viagem / Passeios / Turismo | B34: ='Abr''26'!J14 -> 0 | C34: =IF($B$36=0,"-",B34/$B$36) -> - | E34: Viagem / Passeios / Turismo | F34: ='Mai''26'!J14 -> 0 | G34: =IF($F$36=0,"-",F34/$F$36) -> - | I34: Viagem / Passeios / Turismo | J34: ='Jun''26'!J14 -> 0 | K34: =IF($J$36=0,"-",J34/$J$36) -> -
A36: Total | B36: =SUM(B23:B34) -> 0 | C36: =SUM(C23:C34) -> 0 | E36: Total | F36: =SUM(F23:F34) -> 0 | G36: =SUM(G23:G34) -> 0 | I36: Total | J36: =SUM(J23:J34) -> 0 | K36: =SUM(K23:K34) -> 0
A39: Julho 2026 | E39: Agosto 2026 | I39: Setembro 2026
A40: Origem da Despesa | B40: Valor | C40: Porcentagem | E40: Origem da Despesa | F40: Valor | G40: Porcentagem | I40: Origem da Despesa | J40: Valor | K40: Porcentagem
A41: Alimentação / Nutrição | B41: ='Jul''26'!J3 -> 0 | C41: =IF($B$54=0,"-",B41/$B$54) -> - | E41: Alimentação / Nutrição | F41: ='Ago''26'!J3 -> 0 | G41: =IF($F$54=0,"-",F41/$F$54) -> - | I41: Alimentação / Nutrição | J41: ='Set''26'!J3 -> 0 | K41: =IF($J$54=0,"-",J41/$J$54) -> -
A42: Carro / Transporte | B42: ='Jul''26'!J4 -> 0 | C42: =IF($B$54=0,"-",B42/$B$54) -> - | E42: Carro / Transporte | F42: ='Ago''26'!J4 -> 0 | G42: =IF($F$54=0,"-",F42/$F$54) -> - | I42: Carro / Transporte | J42: ='Set''26'!J4 -> 0 | K42: =IF($J$54=0,"-",J42/$J$54) -> -
A43: Casa / Moradia | B43: ='Jul''26'!J5 -> 0 | C43: =IF($B$54=0,"-",B43/$B$54) -> - | E43: Casa / Moradia | F43: ='Ago''26'!J5 -> 0 | G43: =IF($F$54=0,"-",F43/$F$54) -> - | I43: Casa / Moradia | J43: ='Set''26'!J5 -> 0 | K43: =IF($J$54=0,"-",J43/$J$54) -> -
A44: Celular / Computador | B44: ='Jul''26'!J6 -> 0 | C44: =IF($B$54=0,"-",B44/$B$54) -> - | E44: Celular / Computador | F44: ='Ago''26'!J6 -> 0 | G44: =IF($F$54=0,"-",F44/$F$54) -> - | I44: Celular / Computador | J44: ='Set''26'!J6 -> 0 | K44: =IF($J$54=0,"-",J44/$J$54) -> -
A45: Desenvolvimento Pessoal | B45: ='Jul''26'!J7 -> 0 | C45: =IF($B$54=0,"-",B45/$B$54) -> - | E45: Desenvolvimento Pessoal | F45: ='Ago''26'!J7 -> 0 | G45: =IF($F$54=0,"-",F45/$F$54) -> - | I45: Desenvolvimento Pessoal | J45: ='Set''26'!J7 -> 0 | K45: =IF($J$54=0,"-",J45/$J$54) -> -
A46: Farmácia / Medicamentos | B46: ='Jul''26'!J8 -> 0 | C46: =IF($B$54=0,"-",B46/$B$54) -> - | E46: Farmácia / Medicamentos | F46: ='Ago''26'!J8 -> 0 | G46: =IF($F$54=0,"-",F46/$F$54) -> - | I46: Farmácia / Medicamentos | J46: ='Set''26'!J8 -> 0 | K46: =IF($J$54=0,"-",J46/$J$54) -> -
A47: Filantropia / Doação | B47: ='Jul''26'!J9 -> 0 | C47: =IF($B$54=0,"-",B47/$B$54) -> - | E47: Filantropia / Doação | F47: ='Ago''26'!J9 -> 0 | G47: =IF($F$54=0,"-",F47/$F$54) -> - | I47: Filantropia / Doação | J47: ='Set''26'!J9 -> 0 | K47: =IF($J$54=0,"-",J47/$J$54) -> -
...

Sheet Receitas
A1: Rev.00 - 01/01/2026
A3: Jan'26 | C3: Fev'26 | E3: Mar'26 | G3: Abr'26 | I3: Mai'26 | K3: Jun'26
A4: Descrição | B4: Valor | C4: Descrição | D4: Valor | E4: Descrição | F4: Valor | G4: Descrição | H4: Valor | I4: Descrição | J4: Valor | K4: Descrição | L4: Valor
A14: Total | B14: =SUM(B5:B12) -> 0 | C14: Total | D14: =SUM(D5:D12) -> 0 | E14: Total | F14: =SUM(F5:F12) -> 0 | G14: Total | H14: =SUM(H5:H12) -> 0 | I14: Total | J14: =SUM(J5:J12) -> 0 | K14: Total | L14: =SUM(L5:L12) -> 0
A16: Jul'26 | C16: Ago'26 | E16: Set'26 | G16: Out'26 | I16: Nov'26 | K16: Dez'26
A17: Descrição | B17: Valor | C17: Descrição | D17: Valor | E17: Descrição | F17: Valor | G17: Descrição | H17: Valor | I17: Descrição | J17: Valor | K17: Descrição | L17: Valor
A27: Total | B27: =SUM(B18:B25) -> 0 | C27: Total | D27: =SUM(D18:D25) -> 0 | E27: Total | F27: =SUM(F18:F25) -> 0 | G27: Total | H27: =SUM(H18:H25) -> 0 | I27: Total | J27: =SUM(J18:J25) -> 0 | K27: Total | L27: =SUM(L18:L25) -> 0
F32: Total Geral | G32: =SUM(B14,D14,F14,H14,J14,L14,B27,D27,F27,H27,J27,L27) -> 0

Sheet Jan'26
A1: Planilha Organização Financeira | E1: Rev.00 - 01/01/2026
A2: Descrição da Despesa | B2: Valor | C2: Data | D2: Origem da Despesa | E2: Motivador | I2: Origem da Despesa | J2: Valor | K2: Porcentagem
I3: Alimentação / Nutrição | J3: =SUMIF(D3:D100,I3,B3:B100) -> 0 | K3: =IF($J$16=0,"-",J3/$J$16) -> -
I4: Carro / Transporte | J4: =SUMIF(D3:D100,I4,B3:B100) -> 0 | K4: =IF($J$16=0,"-",J4/$J$16) -> -
I5: Casa / Moradia | J5: =SUMIF(D3:D100,I5,B3:B100) -> 0 | K5: =IF($J$16=0,"-",J5/$J$16) -> -
I6: Celular / Computador | J6: =SUMIF(D3:D100,I6,B3:B100) -> 0 | K6: =IF($J$16=0,"-",J6/$J$16) -> -
I7: Desenvolvimento Pessoal | J7: =SUMIF(D3:D100,I7,B3:B100) -> 0 | K7: =IF($J$16=0,"-",J7/$J$16) -> -
I8: Farmácia / Medicamentos | J8: =SUMIF(D3:D100,I8,B3:B100) -> 0 | K8: =IF($J$16=0,"-",J8/$J$16) -> -
I9: Filantropia / Doação | J9: =SUMIF(D3:D100,I9,B3:B100) -> 0 | K9: =IF($J$16=0,"-",J9/$J$16) -> -
I10: Higiene / Estética / Bem-estar | J10: =SUMIF(D3:D100,I10,B3:B100) -> 0 | K10: =IF($J$16=0,"-",J10/$J$16) -> -
I11: Lazer / Supérfluos | J11: =SUMIF(D3:D100,I11,B3:B100) -> 0 | K11: =IF($J$16=0,"-",J11/$J$16) -> -
I12: Miscelâneas | J12: =SUMIF(D3:D100,I12,B3:B100) -> 0 | K12: =IF($J$16=0,"-",J12/$J$16) -> -
I13: Vestuário | J13: =SUMIF(D3:D100,I13,B3:B100) -> 0 | K13: =IF($J$16=0,"-",J13/$J$16) -> -
I14: Viagem / Passeios / Turismo | J14: =SUMIF(D3:D100,I14,B3:B100) -> 0 | K14: =IF($J$16=0,"-",J14/$J$16) -> -
I16: Total | J16: =SUM(J3:J14) -> 0 | K16: =SUM(K3:K14) -> 0
B102: =SUBTOTAL(9,B3:B100) -> 0

Sheet Fev'26
A1: Planilha Organização Financeira | E1: Rev.00 - 01/01/2026
A2: Descrição da Despesa | B2: Valor | C2: Data | D2: Origem da Despesa | E2: Motivador | I2: Origem da Despesa | J2: Valor | K2: Porcentagem
I3: Alimentação / Nutrição | J3: =SUMIF(D3:D100,I3,B3:B100) -> 0 | K3: =IF($J$16=0,"-",J3/$J$16) -> -
I4: Carro / Transporte | J4: =SUMIF(D3:D100,I4,B3:B100) -> 0 | K4: =IF($J$16=0,"-",J4/$J$16) -> -
I5: Casa / Moradia | J5: =SUMIF(D3:D100,I5,B3:B100) -> 0 | K5: =IF($J$16=0,"-",J5/$J$16) -> -
I6: Celular / Computador | J6: =SUMIF(D3:D100,I6,B3:B100) -> 0 | K6: =IF($J$16=0,"-",J6/$J$16) -> -
I7: Desenvolvimento Pessoal | J7: =SUMIF(D3:D100,I7,B3:B100) -> 0 | K7: =IF($J$16=0,"-",J7/$J$16) -> -
I8: Farmácia / Medicamentos | J8: =SUMIF(D3:D100,I8,B3:B100) -> 0 | K8: =IF($J$16=0,"-",J8/$J$16) -> -
I9: Filantropia / Doação | J9: =SUMIF(D3:D100,I9,B3:B100) -> 0 | K9: =IF($J$16=0,"-",J9/$J$16) -> -
I10: Higiene / Estética / Bem-estar | J10: =SUMIF(D3:D100,I10,B3:B100) -> 0 | K10: =IF($J$16=0,"-",J10/$J$16) -> -
I11: Lazer / Supérfluos | J11: =SUMIF(D3:D100,I11,B3:B100) -> 0 | K11: =IF($J$16=0,"-",J11/$J$16) -> -
I12: Miscelâneas | J12: =SUMIF(D3:D100,I12,B3:B100) -> 0 | K12: =IF($J$16=0,"-",J12/$J$16) -> -
I13: Vestuário | J13: =SUMIF(D3:D100,I13,B3:B100) -> 0 | K13: =IF($J$16=0,"-",J13/$J$16) -> -
I14: Viagem / Passeios / Turismo | J14: =SUMIF(D3:D100,I14,B3:B100) -> 0 | K14: =IF($J$16=0,"-",J14/$J$16) -> -
I16: Total | J16: =SUM(J3:J14) -> 0 | K16: =SUM(K3:K14) -> 0
B102: =SUBTOTAL(9,B3:B100) -> 0

Sheet Mar'26
A1: Planilha Organização Financeira | E1: Rev.00 - 01/01/2026
A2: Descrição da Despesa | B2: Valor | C2: Data | D2: Origem da Despesa | E2: Motivador | I2: Origem da Despesa | J2: Valor | K2: Porcentagem
I3: Alimentação / Nutrição | J3: =SUMIF(D3:D100,I3,B3:B100) -> 0 | K3: =IF($J$16=0,"-",J3/$J$16) -> -
I4: Carro / Transporte | J4: =SUMIF(D3:D100,I4,B3:B100) -> 0 | K4: =IF($J$16=0,"-",J4/$J$16) -> -
I5: Casa / Moradia | J5: =SUMIF(D3:D100,I5,B3:B100) -> 0 | K5: =IF($J$16=0,"-",J5/$J$16) -> -
I6: Celular / Computador | J6: =SUMIF(D3:D100,I6,B3:B100) -> 0 | K6: =IF($J$16=0,"-",J6/$J$16) -> -
I7: Desenvolvimento Pessoal | J7: =SUMIF(D3:D100,I7,B3:B100) -> 0 | K7: =IF($J$16=0,"-",J7/$J$16) -> -
I8: Farmácia / Medicamentos | J8: =SUMIF(D3:D100,I8,B3:B100) -> 0 | K8: =IF($J$16=0,"-",J8/$J$16) -> -
I9: Filantropia / Doação | J9: =SUMIF(D3:D100,I9,B3:B100) -> 0 | K9: =IF($J$16=0,"-",J9/$J$16) -> -
I10: Higiene / Estética / Bem-estar | J10: =SUMIF(D3:D100,I10,B3:B100) -> 0 | K10: =IF($J$16=0,"-",J10/$J$16) -> -
I11: Lazer / Supérfluos | J11: =SUMIF(D3:D100,I11,B3:B100) -> 0 | K11: =IF($J$16=0,"-",J11/$J$16) -> -
I12: Miscelâneas | J12: =SUMIF(D3:D100,I12,B3:B100) -> 0 | K12: =IF($J$16=0,"-",J12/$J$16) -> -
I13: Vestuário | J13: =SUMIF(D3:D100,I13,B3:B100) -> 0 | K13: =IF($J$16=0,"-",J13/$J$16) -> -
I14: Viagem / Passeios / Turismo | J14: =SUMIF(D3:D100,I14,B3:B100) -> 0 | K14: =IF($J$16=0,"-",J14/$J$16) -> -
I16: Total | J16: =SUM(J3:J14) -> 0 | K16: =SUM(K3:K14) -> 0
B102: =SUBTOTAL(9,B3:B100) -> 0

Sheet Abr'26
A1: Planilha Organização Financeira | E1: Rev.00 - 01/01/2026
A2: Descrição da Despesa | B2: Valor | C2: Data | D2: Origem da Despesa | E2: Motivador | I2: Origem da Despesa | J2: Valor | K2: Porcentagem
I3: Alimentação / Nutrição | J3: =SUMIF(D3:D100,I3,B3:B100) -> 0 | K3: =IF($J$16=0,"-",J3/$J$16) -> -
I4: Carro / Transporte | J4: =SUMIF(D3:D100,I4,B3:B100) -> 0 | K4: =IF($J$16=0,"-",J4/$J$16) -> -
I5: Casa / Moradia | J5: =SUMIF(D3:D100,I5,B3:B100) -> 0 | K5: =IF($J$16=0,"-",J5/$J$16) -> -
I6: Celular / Computador | J6: =SUMIF(D3:D100,I6,B3:B100) -> 0 | K6: =IF($J$16=0,"-",J6/$J$16) -> -
I7: Desenvolvimento Pessoal | J7: =SUMIF(D3:D100,I7,B3:B100) -> 0 | K7: =IF($J$16=0,"-",J7/$J$16) -> -
I8: Farmácia / Medicamentos | J8: =SUMIF(D3:D100,I8,B3:B100) -> 0 | K8: =IF($J$16=0,"-",J8/$J$16) -> -
I9: Filantropia / Doação | J9: =SUMIF(D3:D100,I9,B3:B100) -> 0 | K9: =IF($J$16=0,"-",J9/$J$16) -> -
I10: Higiene / Estética / Bem-estar | J10: =SUMIF(D3:D100,I10,B3:B100) -> 0 | K10: =IF($J$16=0,"-",J10/$J$16) -> -
I11: Lazer / Supérfluos | J11: =SUMIF(D3:D100,I11,B3:B100) -> 0 | K11: =IF($J$16=0,"-",J11/$J$16) -> -
I12: Miscelâneas | J12: =SUMIF(D3:D100,I12,B3:B100) -> 0 | K12: =IF($J$16=0,"-",J12/$J$16) -> -
I13: Vestuário | J13: =SUMIF(D3:D100,I13,B3:B100) -> 0 | K13: =IF($J$16=0,"-",J13/$J$16) -> -
I14: Viagem / Passeios / Turismo | J14: =SUMIF(D3:D100,I14,B3:B100) -> 0 | K14: =IF($J$16=0,"-",J14/$J$16) -> -
I16: Total | J16: =SUM(J3:J14) -> 0 | K16: =SUM(K3:K14) -> 0
B102: =SUBTOTAL(9,B3:B100) -> 0

Sheet Mai'26
A1: Planilha Organização Financeira | E1: Rev.00 - 01/01/2026
A2: Descrição da Despesa | B2: Valor | C2: Data | D2: Origem da Despesa | E2: Motivador | I2: Origem da Despesa | J2: Valor | K2: Porcentagem
I3: Alimentação / Nutrição | J3: =SUMIF(D3:D100,I3,B3:B100) -> 0 | K3: =IF($J$16=0,"-",J3/$J$16) -> -
I4: Carro / Transporte | J4: =SUMIF(D3:D100,I4,B3:B100) -> 0 | K4: =IF($J$16=0,"-",J4/$J$16) -> -
I5: Casa / Moradia | J5: =SUMIF(D3:D100,I5,B3:B100) -> 0 | K5: =IF($J$16=0,"-",J5/$J$16) -> -
I6: Celular / Computador | J6: =SUMIF(D3:D100,I6,B3:B100) -> 0 | K6: =IF($J$16=0,"-",J6/$J$16) -> -
I7: Desenvolvimento Pessoal | J7: =SUMIF(D3:D100,I7,B3:B100) -> 0 | K7: =IF($J$16=0,"-",J7/$J$16) -> -
I8: Farmácia / Medicamentos | J8: =SUMIF(D3:D100,I8,B3:B100) -> 0 | K8: =IF($J$16=0,"-",J8/$J$16) -> -
I9: Filantropia / Doação | J9: =SUMIF(D3:D100,I9,B3:B100) -> 0 | K9: =IF($J$16=0,"-",J9/$J$16) -> -
I10: Higiene / Estética / Bem-estar | J10: =SUMIF(D3:D100,I10,B3:B100) -> 0 | K10: =IF($J$16=0,"-",J10/$J$16) -> -
I11: Lazer / Supérfluos | J11: =SUMIF(D3:D100,I11,B3:B100) -> 0 | K11: =IF($J$16=0,"-",J11/$J$16) -> -
I12: Miscelâneas | J12: =SUMIF(D3:D100,I12,B3:B100) -> 0 | K12: =IF($J$16=0,"-",J12/$J$16) -> -
I13: Vestuário | J13: =SUMIF(D3:D100,I13,B3:B100) -> 0 | K13: =IF($J$16=0,"-",J13/$J$16) -> -
I14: Viagem / Passeios / Turismo | J14: =SUMIF(D3:D100,I14,B3:B100) -> 0 | K14: =IF($J$16=0,"-",J14/$J$16) -> -
I16: Total | J16: =SUM(J3:J14) -> 0 | K16: =SUM(K3:K14) -> 0
B102: =SUBTOTAL(9,B3:B100) -> 0

Sheet Jun'26
A1: Planilha Organização Financeira | E1: Rev.00 - 01/01/2026
A2: Descrição da Despesa | B2: Valor | C2: Data | D2: Origem da Despesa | E2: Motivador | I2: Origem da Despesa | J2: Valor | K2: Porcentagem
I3: Alimentação / Nutrição | J3: =SUMIF(D3:D100,I3,B3:B100) -> 0 | K3: =IF($J$16=0,"-",J3/$J$16) -> -
I4: Carro / Transporte | J4: =SUMIF(D3:D100,I4,B3:B100) -> 0 | K4: =IF($J$16=0,"-",J4/$J$16) -> -
I5: Casa / Moradia | J5: =SUMIF(D3:D100,I5,B3:B100) -> 0 | K5: =IF($J$16=0,"-",J5/$J$16) -> -
I6: Celular / Computador | J6: =SUMIF(D3:D100,I6,B3:B100) -> 0 | K6: =IF($J$16=0,"-",J6/$J$16) -> -
I7: Desenvolvimento Pessoal | J7: =SUMIF(D3:D100,I7,B3:B100) -> 0 | K7: =IF($J$16=0,"-",J7/$J$16) -> -
I8: Farmácia / Medicamentos | J8: =SUMIF(D3:D100,I8,B3:B100) -> 0 | K8: =IF($J$16=0,"-",J8/$J$16) -> -
I9: Filantropia / Doação | J9: =SUMIF(D3:D100,I9,B3:B100) -> 0 | K9: =IF($J$16=0,"-",J9/$J$16) -> -
I10: Higiene / Estética / Bem-estar | J10: =SUMIF(D3:D100,I10,B3:B100) -> 0 | K10: =IF($J$16=0,"-",J10/$J$16) -> -
I11: Lazer / Supérfluos | J11: =SUMIF(D3:D100,I11,B3:B100) -> 0 | K11: =IF($J$16=0,"-",J11/$J$16) -> -
I12: Miscelâneas | J12: =SUMIF(D3:D100,I12,B3:B100) -> 0 | K12: =IF($J$16=0,"-",J12/$J$16) -> -
I13: Vestuário | J13: =SUMIF(D3:D100,I13,B3:B100) -> 0 | K13: =IF($J$16=0,"-",J13/$J$16) -> -
I14: Viagem / Passeios / Turismo | J14: =SUMIF(D3:D100,I14,B3:B100) -> 0 | K14: =IF($J$16=0,"-",J14/$J$16) -> -
I16: Total | J16: =SUM(J3:J14) -> 0 | K16: =SUM(K3:K14) -> 0
B102: =SUBTOTAL(9,B3:B100) -> 0

Sheet Jul'26
A1: Planilha Organização Financeira | E1: Rev.00 - 01/01/2026
A2: Descrição da Despesa | B2: Valor | C2: Data | D2: Origem da Despesa | E2: Motivador | I2: Origem da Despesa | J2: Valor | K2: Porcentagem
I3: Alimentação / Nutrição | J3: =SUMIF(D3:D100,I3,B3:B100) -> 0 | K3: =IF($J$16=0,"-",J3/$J$16) -> -
I4: Carro / Transporte | J4: =SUMIF(D3:D100,I4,B3:B100) -> 0 | K4: =IF($J$16=0,"-",J4/$J$16) -> -
I5: Casa / Moradia | J5: =SUMIF(D3:D100,I5,B3:B100) -> 0 | K5: =IF($J$16=0,"-",J5/$J$16) -> -
I6: Celular / Computador | J6: =SUMIF(D3:D100,I6,B3:B100) -> 0 | K6: =IF($J$16=0,"-",J6/$J$16) -> -
I7: Desenvolvimento Pessoal | J7: =SUMIF(D3:D100,I7,B3:B100) -> 0 | K7: =IF($J$16=0,"-",J7/$J$16) -> -
I8: Farmácia / Medicamentos | J8: =SUMIF(D3:D100,I8,B3:B100) -> 0 | K8: =IF($J$16=0,"-",J8/$J$16) -> -
I9: Filantropia / Doação | J9: =SUMIF(D3:D100,I9,B3:B100) -> 0 | K9: =IF($J$16=0,"-",J9/$J$16) -> -
I10: Higiene / Estética / Bem-estar | J10: =SUMIF(D3:D100,I10,B3:B100) -> 0 | K10: =IF($J$16=0,"-",J10/$J$16) -> -
I11: Lazer / Supérfluos | J11: =SUMIF(D3:D100,I11,B3:B100) -> 0 | K11: =IF($J$16=0,"-",J11/$J$16) -> -
I12: Miscelâneas | J12: =SUMIF(D3:D100,I12,B3:B100) -> 0 | K12: =IF($J$16=0,"-",J12/$J$16) -> -
I13: Vestuário | J13: =SUMIF(D3:D100,I13,B3:B100) -> 0 | K13: =IF($J$16=0,"-",J13/$J$16) -> -
I14: Viagem / Passeios / Turismo | J14: =SUMIF(D3:D100,I14,B3:B100) -> 0 | K14: =IF($J$16=0,"-",J14/$J$16) -> -
I16: Total | J16: =SUM(J3:J14) -> 0 | K16: =SUM(K3:K14) -> 0
B102: =SUBTOTAL(9,B3:B100) -> 0

Sheet Ago'26
A1: Planilha Organização Financeira | E1: Rev.00 - 01/01/2026
A2: Descrição da Despesa | B2: Valor | C2: Data | D2: Origem da Despesa | E2: Motivador | I2: Origem da Despesa | J2: Valor | K2: Porcentagem
I3: Alimentação / Nutrição | J3: =SUMIF(D3:D100,I3,B3:B100) -> 0 | K3: =IF($J$16=0,"-",J3/$J$16) -> -
I4: Carro / Transporte | J4: =SUMIF(D3:D100,I4,B3:B100) -> 0 | K4: =IF($J$16=0,"-",J4/$J$16) -> -
I5: Casa / Moradia | J5: =SUMIF(D3:D100,I5,B3:B100) -> 0 | K5: =IF($J$16=0,"-",J5/$J$16) -> -
I6: Celular / Computador | J6: =SUMIF(D3:D100,I6,B3:B100) -> 0 | K6: =IF($J$16=0,"-",J6/$J$16) -> -
I7: Desenvolvimento Pessoal | J7: =SUMIF(D3:D100,I7,B3:B100) -> 0 | K7: =IF($J$16=0,"-",J7/$J$16) -> -
I8: Farmácia / Medicamentos | J8: =SUMIF(D3:D100,I8,B3:B100) -> 0 | K8: =IF($J$16=0,"-",J8/$J$16) -> -
I9: Filantropia / Doação | J9: =SUMIF(D3:D100,I9,B3:B100) -> 0 | K9: =IF($J$16=0,"-",J9/$J$16) -> -
I10: Higiene / Estética / Bem-estar | J10: =SUMIF(D3:D100,I10,B3:B100) -> 0 | K10: =IF($J$16=0,"-",J10/$J$16) -> -
I11: Lazer / Supérfluos | J11: =SUMIF(D3:D100,I11,B3:B100) -> 0 | K11: =IF($J$16=0,"-",J11/$J$16) -> -
I12: Miscelâneas | J12: =SUMIF(D3:D100,I12,B3:B100) -> 0 | K12: =IF($J$16=0,"-",J12/$J$16) -> -
I13: Vestuário | J13: =SUMIF(D3:D100,I13,B3:B100) -> 0 | K13: =IF($J$16=0,"-",J13/$J$16) -> -
I14: Viagem / Passeios / Turismo | J14: =SUMIF(D3:D100,I14,B3:B100) -> 0 | K14: =IF($J$16=0,"-",J14/$J$16) -> -
I16: Total | J16: =SUM(J3:J14) -> 0 | K16: =SUM(K3:K14) -> 0
B102: =SUBTOTAL(9,B3:B100) -> 0

Sheet Set'26
A1: Planilha Organização Financeira | E1: Rev.00 - 01/01/2026
A2: Descrição da Despesa | B2: Valor | C2: Data | D2: Origem da Despesa | E2: Motivador | I2: Origem da Despesa | J2: Valor | K2: Porcentagem
I3: Alimentação / Nutrição | J3: =SUMIF(D3:D100,I3,B3:B100) -> 0 | K3: =IF($J$16=0,"-",J3/$J$16) -> -
I4: Carro / Transporte | J4: =SUMIF(D3:D100,I4,B3:B100) -> 0 | K4: =IF($J$16=0,"-",J4/$J$16) -> -
I5: Casa / Moradia | J5: =SUMIF(D3:D100,I5,B3:B100) -> 0 | K5: =IF($J$16=0,"-",J5/$J$16) -> -
I6: Celular / Computador | J6: =SUMIF(D3:D100,I6,B3:B100) -> 0 | K6: =IF($J$16=0,"-",J6/$J$16) -> -
I7: Desenvolvimento Pessoal | J7: =SUMIF(D3:D100,I7,B3:B100) -> 0 | K7: =IF($J$16=0,"-",J7/$J$16) -> -
I8: Farmácia / Medicamentos | J8: =SUMIF(D3:D100,I8,B3:B100) -> 0 | K8: =IF($J$16=0,"-",J8/$J$16) -> -
I9: Filantropia / Doação | J9: =SUMIF(D3:D100,I9,B3:B100) -> 0 | K9: =IF($J$16=0,"-",J9/$J$16) -> -
I10: Higiene / Estética / Bem-estar | J10: =SUMIF(D3:D100,I10,B3:B100) -> 0 | K10: =IF($J$16=0,"-",J10/$J$16) -> -
I11: Lazer / Supérfluos | J11: =SUMIF(D3:D100,I11,B3:B100) -> 0 | K11: =IF($J$16=0,"-",J11/$J$16) -> -
I12: Miscelâneas | J12: =SUMIF(D3:D100,I12,B3:B100) -> 0 | K12: =IF($J$16=0,"-",J12/$J$16) -> -
I13: Vestuário | J13: =SUMIF(D3:D100,I13,B3:B100) -> 0 | K13: =IF($J$16=0,"-",J13/$J$16) -> -
I14: Viagem / Passeios / Turismo | J14: =SUMIF(D3:D100,I14,B3:B100) -> 0 | K14: =IF($J$16=0,"-",J14/$J$16) -> -
I16: Total | J16: =SUM(J3:J14) -> 0 | K16: =SUM(K3:K14) -> 0
B102: =SUBTOTAL(9,B3:B100) -> 0

Sheet Out'26
A1: Planilha Organização Financeira | E1: Rev.00 - 01/01/2026
A2: Descrição da Despesa | B2: Valor | C2: Data | D2: Origem da Despesa | E2: Motivador | I2: Origem da Despesa | J2: Valor | K2: Porcentagem
I3: Alimentação / Nutrição | J3: =SUMIF(D3:D100,I3,B3:B100) -> 0 | K3: =IF($J$16=0,"-",J3/$J$16) -> -
I4: Carro / Transporte | J4: =SUMIF(D3:D100,I4,B3:B100) -> 0 | K4: =IF($J$16=0,"-",J4/$J$16) -> -
I5: Casa / Moradia | J5: =SUMIF(D3:D100,I5,B3:B100) -> 0 | K5: =IF($J$16=0,"-",J5/$J$16) -> -
I6: Celular / Computador | J6: =SUMIF(D3:D100,I6,B3:B100) -> 0 | K6: =IF($J$16=0,"-",J6/$J$16) -> -
I7: Desenvolvimento Pessoal | J7: =SUMIF(D3:D100,I7,B3:B100) -> 0 | K7: =IF($J$16=0,"-",J7/$J$16) -> -
I8: Farmácia / Medicamentos | J8: =SUMIF(D3:D100,I8,B3:B100) -> 0 | K8: =IF($J$16=0,"-",J8/$J$16) -> -
I9: Filantropia / Doação | J9: =SUMIF(D3:D100,I9,B3:B100) -> 0 | K9: =IF($J$16=0,"-",J9/$J$16) -> -
I10: Higiene / Estética / Bem-estar | J10: =SUMIF(D3:D100,I10,B3:B100) -> 0 | K10: =IF($J$16=0,"-",J10/$J$16) -> -
I11: Lazer / Supérfluos | J11: =SUMIF(D3:D100,I11,B3:B100) -> 0 | K11: =IF($J$16=0,"-",J11/$J$16) -> -
I12: Miscelâneas | J12: =SUMIF(D3:D100,I12,B3:B100) -> 0 | K12: =IF($J$16=0,"-",J12/$J$16) -> -
I13: Vestuário | J13: =SUMIF(D3:D100,I13,B3:B100) -> 0 | K13: =IF($J$16=0,"-",J13/$J$16) -> -
I14: Viagem / Passeios / Turismo | J14: =SUMIF(D3:D100,I14,B3:B100) -> 0 | K14: =IF($J$16=0,"-",J14/$J$16) -> -
I16: Total | J16: =SUM(J3:J14) -> 0 | K16: =SUM(K3:K14) -> 0
B102: =SUBTOTAL(9,B3:B100) -> 0

Sheet Nov'26
A1: Planilha Organização Financeira | E1: Rev.00 - 01/01/2026
A2: Descrição da Despesa | B2: Valor | C2: Data | D2: Origem da Despesa | E2: Motivador | I2: Origem da Despesa | J2: Valor | K2: Porcentagem
I3: Alimentação / Nutrição | J3: =SUMIF(D3:D100,I3,B3:B100) -> 0 | K3: =IF($J$16=0,"-",J3/$J$16) -> -
I4: Carro / Transporte | J4: =SUMIF(D3:D100,I4,B3:B100) -> 0 | K4: =IF($J$16=0,"-",J4/$J$16) -> -
I5: Casa / Moradia | J5: =SUMIF(D3:D100,I5,B3:B100) -> 0 | K5: =IF($J$16=0,"-",J5/$J$16) -> -
I6: Celular / Computador | J6: =SUMIF(D3:D100,I6,B3:B100) -> 0 | K6: =IF($J$16=0,"-",J6/$J$16) -> -
I7: Desenvolvimento Pessoal | J7: =SUMIF(D3:D100,I7,B3:B100) -> 0 | K7: =IF($J$16=0,"-",J7/$J$16) -> -
I8: Farmácia / Medicamentos | J8: =SUMIF(D3:D100,I8,B3:B100) -> 0 | K8: =IF($J$16=0,"-",J8/$J$16) -> -
I9: Filantropia / Doação | J9: =SUMIF(D3:D100,I9,B3:B100) -> 0 | K9: =IF($J$16=0,"-",J9/$J$16) -> -
I10: Higiene / Estética / Bem-estar | J10: =SUMIF(D3:D100,I10,B3:B100) -> 0 | K10: =IF($J$16=0,"-",J10/$J$16) -> -
I11: Lazer / Supérfluos | J11: =SUMIF(D3:D100,I11,B3:B100) -> 0 | K11: =IF($J$16=0,"-",J11/$J$16) -> -
I12: Miscelâneas | J12: =SUMIF(D3:D100,I12,B3:B100) -> 0 | K12: =IF($J$16=0,"-",J12/$J$16) -> -
I13: Vestuário | J13: =SUMIF(D3:D100,I13,B3:B100) -> 0 | K13: =IF($J$16=0,"-",J13/$J$16) -> -
I14: Viagem / Passeios / Turismo | J14: =SUMIF(D3:D100,I14,B3:B100) -> 0 | K14: =IF($J$16=0,"-",J14/$J$16) -> -
I16: Total | J16: =SUM(J3:J14) -> 0 | K16: =SUM(K3:K14) -> 0
B102: =SUBTOTAL(9,B3:B100) -> 0

Sheet Dez'26
A1: Planilha Organização Financeira | E1: Rev.00 - 01/01/2026
A2: Descrição da Despesa | B2: Valor | C2: Data | D2: Origem da Despesa | E2: Motivador | I2: Origem da Despesa | J2: Valor | K2: Porcentagem
I3: Alimentação / Nutrição | J3: =SUMIF(D3:D100,I3,B3:B100) -> 0 | K3: =IF($J$16=0,"-",J3/$J$16) -> -
I4: Carro / Transporte | J4: =SUMIF(D3:D100,I4,B3:B100) -> 0 | K4: =IF($J$16=0,"-",J4/$J$16) -> -
I5: Casa / Moradia | J5: =SUMIF(D3:D100,I5,B3:B100) -> 0 | K5: =IF($J$16=0,"-",J5/$J$16) -> -
I6: Celular / Computador | J6: =SUMIF(D3:D100,I6,B3:B100) -> 0 | K6: =IF($J$16=0,"-",J6/$J$16) -> -
I7: Desenvolvimento Pessoal | J7: =SUMIF(D3:D100,I7,B3:B100) -> 0 | K7: =IF($J$16=0,"-",J7/$J$16) -> -
I8: Farmácia / Medicamentos | J8: =SUMIF(D3:D100,I8,B3:B100) -> 0 | K8: =IF($J$16=0,"-",J8/$J$16) -> -
I9: Filantropia / Doação | J9: =SUMIF(D3:D100,I9,B3:B100) -> 0 | K9: =IF($J$16=0,"-",J9/$J$16) -> -
I10: Higiene / Estética / Bem-estar | J10: =SUMIF(D3:D100,I10,B3:B100) -> 0 | K10: =IF($J$16=0,"-",J10/$J$16) -> -
I11: Lazer / Supérfluos | J11: =SUMIF(D3:D100,I11,B3:B100) -> 0 | K11: =IF($J$16=0,"-",J11/$J$16) -> -
I12: Miscelâneas | J12: =SUMIF(D3:D100,I12,B3:B100) -> 0 | K12: =IF($J$16=0,"-",J12/$J$16) -> -
I13: Vestuário | J13: =SUMIF(D3:D100,I13,B3:B100) -> 0 | K13: =IF($J$16=0,"-",J13/$J$16) -> -
I14: Viagem / Passeios / Turismo | J14: =SUMIF(D3:D100,I14,B3:B100) -> 0 | K14: =IF($J$16=0,"-",J14/$J$16) -> -
I16: Total | J16: =SUM(J3:J14) -> 0 | K16: =SUM(K3:K14) -> 0
B102: =SUBTOTAL(9,B3:B100) -> 0

Sheet Revisões
A1: Revisão | B1: Data | C1: Motivo | F1: Origem da Despesa
A2: Rev.00 | B2: 46023 | C2: Criação da planilha | F2: Alimentação / Nutrição
F3: Carro / Transporte
F4: Casa / Moradia
F5: Celular / Computador
F6: Desenvolvimento Pessoal
F7: Farmácia / Medicamentos
F8: Filantropia / Doação
F9: Higiene / Estética / Bem-estar
F10: Lazer / Supérfluos
F11: Miscelâneas
F12: Vestuário
F13: Viagem / Passeios / Turismo
F16: Motivador
... F18: Não Essencial
